Workbook
Name Categorie: Data!$A$2:$A$7

Sheet Toelichting
C6: FASE | D6: TYPE STANDAARD / BENAMING | E6: NAUWKEURIGHEID | F6: TOELICHTING | G6: OPMERKINGEN
C7: Initiatief / Definitie | D7: Budgetindicatie (van-tot) | E7: Grote kengetallen | F7: Minimaal v.s. Maximaal | G7: Afronden 1000,- | H7: min-max
C8: SO - VO | D8: Indicatieve kostenraming | E8: Kengetallen o.b.v. eenheden | G8: Afronden 100,- | H8: +/- 5-10%
C9: Definitief Ontwerp / VO+ | D9: Kostencalculatie | E9: Offertes o.a. | G9: Afronden 10/1,- | H9: offerte
C12: STAPPENPLAN
B13: 1 | C13: Vul in tabblad "1|Voorblad" de gegevens handmatig in.
B14: 2 | C14: Vul in tabblad "2|Totaalblad" de projectgegevens in.
B15: 3 | C15: Vul in tabblad "3|Totaalblad" het onderdeel 45000 Algemeen in.
B16: 4 | C16: …
B17: 5 | C17: …
B18: 6 | C18: …
B19: 7 | C19: …
B20: 8 | C20: …
C23: HANDIGHEIDJES
C24: Rechtsbovenin staat het totaalbedrag van de raming/begroting.
C25: Gebruik meetstaten om het jezelf makkelijk te maken! --> zie kopje 'meetstaten' voor toelichting.
C26: Maak gebruik van kengetallen.
C27: Meerdere tabbladen in één keer printen --> uitleg (gebruik van control).
C30: BELANGRIJKE REGELS
B31: 1 | C31: Notatie wat je laat zien aan opdrachtgever.
C39: --> Deze manier laat (zeker in eerste raming) te hoge nauwkeurigheid zien.
C40: --> Notatie op posten verminderd de kans dat opdrachtgever zelf zaken gaat verrekenen.
B43: 2 | C43: Totaalblad:
C44: - Cijfers worden zwart wanneer er een bedrag in de begroting wordt ingevuld.
C53: HULP BIJ AFRONDEN IN RAMING
C77: KENGETALLEN - N.T.B.
C78: N.T.B.

Sheet 1 | Front cover
E21: ='2 | Basic principles'!C7
E23: ='2 | Basic principles'!C8
E24: ='2 | Basic principles'!C9
E25: ='2 | Basic principles'!F9

Sheet 2 | Basic principles
A7: PROJECT | C7: [PROJECTNAAM]
C8: Inkoopoverzicht leveranciers (offertes & opdrachten) | D8: DATE | E8: Line-up | F8: 46186
C9: Versie 001 | E9: Change | F9: 46186
A11: Code | B11: Description
A14: 000 | B14: GENERAL
A16: 010 | B16: PROJECT DETAILS
B17: * | C17: Client's contact details
B18: * | C18: Construction site address
B19: * | C19: Brief description of the work
A22: 020 | B22: DIMENSIONS
C23: Ground floor | D23: m² | E23: 0
C24: First floor | D24: m² | E24: 0
C25: Second floor | D25: m² | E25: 0
C26: … | D26: m² | E26: 0.0001
C27: Total | D27: m² | E27: =SUM(E23:E26)
A30: 030 | B30: BASIC PRINCIPLES
C31: Phase documents
C32: Architect's drawings dated
C33: Report dated
C34: Photos dated
C35: Impressions dated
C36: Presentation dated
C38: Project-specific
C39: Communication with tenants by the client
C40: No loose fixtures and fittings in the transfer of the premises
C41: …
C42: …
C43: …
... C53: …
B56: EXPLANATION OF THE PHASE
C57: Indicative cost estimate
C58: …
C59: …
C60: …
C61: …

Sheet 3 | Summary sheet
A7: PROJECT | C7: ='2 | Basic principles'!C7 | I7: Totaal m²
C8: ='2 | Basic principles'!C8 | D8: DATE | E8: Line-up | F8: ='2 | Basic principles'!F8
C9: ='2 | Basic principles'!C9 | E9: Change | F9: =TODAY() | I9: ='2 | Basic principles'!E27
A11: Code | C11: Description | G11: Total €. | I11: €/m²
A14: 100 | B14: BOUWKUNDIGE WERKZAAMHEDEN & BOUWPLAATS | G14: =SUM(G16:G25) | I14: =SUM(I16:I25)
A16: 110 | B16: INRICHTING BOUWPLAATS & BEGELEIDING | G16: ='4 | Calculation'!G34 | I16: =G16/$I$9
A17: 120 | B17: SLOOPWERKZAAMHEDEN | G17: ='4 | Calculation'!G55 | I17: =G17/$I$9
A18: 131 | B18: DIVERSE BOUWKUNDIGE WERKZAAMHEDEN | G18: ='4 | Calculation'!G64 | I18: =G18/$I$9
A19: 132 | B19: STAIRS | G19: ='4 | Calculation'!G79 | I19: =G19/$I$9
A20: 133 | B20: ENTRANCES | G20: ='4 | Calculation'!G91 | I20: =G20/$I$9
A21: 134 | B21: KITCHEN | G21: ='4 | Calculation'!G114 | I21: =G21/$I$9
A22: 135 | B22: OTHER | G22: ='4 | Calculation'!G123 | I22: =G22/$I$9
A23: 141 | B23: TOILET AREA | G23: ='4 | Calculation'!G145 | I23: =G23/$I$9
A24: 142 | B24: SHOWER | G24: ='4 | Calculation'!G165 | I24: =G24/$I$9
A25: 143 | B25: STORAGE CABINET/FIRST AID/BREAST PUMP ROOM | G25: ='4 | Calculation'!G185 | I25: =G25/$I$9
A27: 200 | B27: INSTALLATION WORKS | G27: =SUM(G29:G34) | I27: =SUM(I29:I34)
A29: 210 | B29: HVAC INSTALLATION | G29: ='4 | Calculation'!G205 | I29: =G29/$I$9
A30: 220 | B30: PLUMBING WORKS | G30: ='4 | Calculation'!G213 | I30: =G30/$I$9
A31: 230 | B31: ELECTRICAL INSTALLATION | G31: ='4 | Calculation'!G237 | I31: =G31/$I$9
A32: 240 | B32: ACCESS CONTROL & SECURITY | G32: ='4 | Calculation'!G257 | I32: =G32/$I$9
A33: 250 | B33: IT INSTALLATION | G33: ='4 | Calculation'!G280 | I33: =G33/$I$9
A34: 260 | B34: FIRE SAFETY | G34: ='4 | Calculation'!G304 | I34: =G34/$I$9
A36: 300 | B36: FINISHING & FIXTURES | G36: =SUM(G38:G49) | I36: =SUM(I38:I49)
A38: 311 | B38: FLOOR FINISHES | G38: ='4 | Calculation'!G314 | I38: =G38/$I$9
A39: 312 | B39: PREMIUM FLOOR FINISHES | G39: ='4 | Calculation'!G320 | I39: =G39/$I$9
A40: 313 | B40: WOODEN FLOORING | G40: ='4 | Calculation'!G327 | I40: =G40/$I$9
A41: 314 | B41: OTHER FLOOR FINISHES | G41: ='4 | Calculation'!G339 | I41: =G41/$I$9
A42: 321 | B42: MS WALLS | G42: ='4 | Calculation'!G354 | I42: =G42/$I$9
A43: 322 | B43: MODULAR WALLS | G43: ='4 | Calculation'!G368 | I43: =G43/$I$9
A44: 323 | B44: OTHER WALLS | G44: ='4 | Calculation'!G372 | I44: =G44/$I$9
A45: 330 | B45: WALL FINISHES | G45: ='4 | Calculation'!G387 | I45: =G45/$I$9
A46: 340 | B46: CEILING | G46: ='4 | Calculation'!G404 | I46: =G46/$I$9
A47: 350 | B47: LIGHTING | G47: ='4 | Calculation'!G420 | I47: =G47/$I$9
A48: 360 | B48: SUN AND LIGHT CONTROL | G48: ='4 | Calculation'!G432 | I48: =G48/$I$9
A49: 370 | B49: BESPOKE FURNITURE | G49: ='4 | Calculation'!G453 | I49: =G49/$I$9
A51: 400 | B51: FREESTANDING FURNISHINGS & DÉCOR | G51: =SUM(G53:G57) | I51: =SUM(I53:I57)
A53: 410 | B53: MEUBILAIR | G53: ='4 | Calculation'!G480 | I53: =G53/$I$9
A54: 420 | B54: LOSSE INRICHTING | G54: ='4 | Calculation'!G494 | I54: =G54/$I$9
A55: 430 | B55: AUDIO VISUELE INSTALLATIE | G55: ='4 | Calculation'!G511 | I55: =G55/$I$9
A56: 440 | B56: AKOESTISCHE VOORZIENINGEN | G56: ='4 | Calculation'!G525 | I56: =G56/$I$9
...

Sheet 4 | Calculation
L6: Verborgen opslagen
A7: PROJECT | C7: ='2 | Basic principles'!C7 | D7: DATE | K7: INFORMATIE | L7: Opslag inkoop | M7: =((V9*1)+1)*((V10*1)+1)*((V11*1)+1)*((V12*1)+1) | O7: TOTAALBEDRAG
C8: ='2 | Basic principles'!C8 | E8: Line-up | F8: ='2 | Basic principles'!F8 | L8: Afronding | M8: 1 | O8: =G623 | T8: Verborgen opslagen
C9: ='2 | Basic principles'!C9 | E9: Change | F9: dd-mm-jjjj | L9: Opslag uren | M9: 1.1 | O9: ='2 | Basic principles'!E27 | R9: m² | T9: Verborgen opslag | V9: 0.1
O10: =O8/O9 | R10: /m² | T10: Onvoorzien | V10: 0.04
A12: Code | C12: Description | D12: Unit | E12: Number | F12: €/unit | G12: Total €. | I12: Party | K12: Aant. | L12: €/Eenh. | M12: Totaal €. | O12: OPMERKING & TOELICHTING
A15: 100 | B15: CONSTRUCTION WORKS & CONSTRUCTION SITE
A17: 110 | B17: CONSTRUCTION SITE SET-UP & SUPERVISION
B18: 1 | C18: Construction site facilities (meeting and canteen area, coffee, toilets and washrooms, etc.). | D18: stelpost | E18: =K18 | F18: =CEILING(L18*$M$7,$M$8) | G18: =ROUND(E18*F18,0) | I18: Bouwkundige | K18: 0 | L18: 500 | M18: =K18*L18
B19: 2 | C19: Safety equipment | D19: stelpost | E19: =K19 | F19: =CEILING(L19*$M$7,$M$8) | G19: =ROUND(E19*F19,0) | I19: Bouwkundige | K19: 0 | L19: 1358 | M19: =K19*L19
B20: 3 | C20: Construction site security (e.g. BouWatch or security guard who walks an opening/closing round each day). | D20: stelpost | E20: =K20 | F20: =CEILING(L20*$M$7,$M$8) | G20: =ROUND(E20*F20,0) | I20: Bouwkundige | K20: 0 | L20: 1254 | M20: =K20*L20
B21: 4 | C21: Guarding (+ lift cladding), covers and dust barriers. | D21: stelpost | E21: =K21 | F21: =CEILING(L21*$M$7,$M$8) | G21: =ROUND(E21*F21,0) | I21: Bouwkundige | K21: 0 | L21: 600 | M21: =K21*L21
B22: 5 | C22: Cleaning during construction. | D22: stelpost | E22: =K22 | F22: =CEILING(L22*$M$7,$M$8) | G22: =ROUND(E22*F22,0) | I22: Bouwkundige | K22: 0 | L22: 2380 | M22: =K22*L22
B23: 6 | C23: Final cleaning before delivery. | D23: stelpost | E23: =K23 | F23: =CEILING(L23*$M$7,$M$8) | G23: =ROUND(E23*F23,0) | I23: Bouwkundige | K23: 0 | L23: 3990 | M23: =K23*L23
B24: 7 | C24: Vertical transport: opening/protecting the façade, temporary provisions, hoisting or provisions for other types of vertical transport. | D24: stelpost | E24: =K24 | F24: =CEILING(L24*$M$7,$M$8) | G24: =ROUND(E24*F24,0) | I24: Bouwkundige | K24: 0 | L24: 1456 | M24: =K24*L24
B25: 8 | C25: Opening and closing the façade (including temporary provisions). | D25: post | E25: =K25 | F25: =CEILING(L25*$M$7,$M$8) | G25: =ROUND(E25*F25,0) | I25: Bouwkundige | K25: 0 | L25: 0 | M25: =K25*L25
B26: 9 | C26: Other costs such as work preparation, execution and site foreman. | D26: post | E26: =K26 | F26: =CEILING(L26*$M$7,$M$8) | G26: =ROUND(E26*F26,0) | I26: Bouwkundige | K26: 0 | L26: 0 | M26: =K26*L26
B27: 10 | C27: Trash containers and scaffolding | D27: p.m. | E27: =K27*M9 | F27: =CEILING(L27,$M$8) | G27: =ROUND(E27*F27,0) | I27: Bouwkundige | K27: 0 | L27: 0 | M27: =K27*L27
B28: 11 | D28: post | E28: =K28 | F28: =CEILING(L28*$M$7,$M$8) | G28: =ROUND(E28*F28,0) | I28: Bouwkundige | K28: 0 | L28: 0 | M28: =K28*L28
B29: 12 | D29: post | E29: =K29 | F29: =CEILING(L29*$M$7,$M$8) | G29: =ROUND(E29*F29,0) | I29: Bouwkundige | K29: 0 | L29: 0 | M29: =K29*L29
B30: 13 | D30: post | E30: =K30 | F30: =CEILING(L30*$M$7,$M$8) | G30: =ROUND(E30*F30,0) | I30: Bouwkundige | K30: 0 | L30: 0 | M30: =K30*L30
B31: 14 | D31: post | E31: =K31 | F31: =CEILING(L31*$M$7,$M$8) | G31: =ROUND(E31*F31,0) | I31: Bouwkundige | K31: 0 | L31: 0 | M31: =K31*L31
B32: 15 | D32: post | E32: =K32 | F32: =CEILING(L32*$M$7,$M$8) | G32: =ROUND(E32*F32,0) | I32: Bouwkundige | K32: 0 | L32: 0 | M32: =K32*L32
B33: 16 | D33: post | E33: =K33 | F33: =CEILING(L33*$M$7,$M$8) | G33: =ROUND(E33*F33,0) | I33: Bouwkundige | K33: 0 | L33: 0 | M33: =K33*L33
G34: =SUM(G18:G33) | M34: =SUM(M18:M33)
A36: 120 | B36: DEMOLITION WORK
B37: 1 | C37: Removing existing flooring in whole floor. | D37: stelpost | E37: =K37 | F37: =CEILING(L37*$M$7,$M$8) | G37: =ROUND(E37*F37,0) | I37: Sloper | K37: 0 | L37: 4697 | M37: =K37*L37
B38: 2 | C38: Chasing in existing sub floors | D38: stelpost | E38: =K38 | F38: =CEILING(L38*$M$7,$M$8) | G38: =ROUND(E38*F38,0) | I38: Sloper | K38: 0 | L38: 2335 | M38: =K38*L38
B39: 3 | C39: Preparatory electrical work for demolition. | D39: post | E39: =K39 | F39: =CEILING(L39*$M$7,$M$8) | I39: Sloper | K39: 0 | L39: 0 | M39: =K39*L39
B40: 4 | C40: Preparatory mechanical work for demolition. | D40: post | E40: =K40 | F40: =CEILING(L40*$M$7,$M$8) | G40: =ROUND(E40*F40,0) | I40: Sloper | K40: 0 | L40: 0 | M40: =K40*L40
B41: 5 | C41: Structural demolition work. [Specify what] | D41: post | E41: =K41 | F41: =CEILING(L41*$M$7,$M$8) | G41: =ROUND(E41*F41,0) | I41: Sloper | K41: 0 | L41: 0 | M41: =K41*L41
B42: 6 | C42: Disconnecting electrical installations for demolition work. [Describe] | D42: post | E42: =K42 | F42: =CEILING(L42*$M$7,$M$8) | G42: =ROUND(E42*F42,0) | I42: Sloper | K42: 0 | L42: 0 | M42: =K42*L42
B43: 7 | C43: Disconnecting mechanical installations for demolition work. [Describe] | D43: post | E43: =K43 | F43: =CEILING(L43*$M$7,$M$8) | G43: =ROUND(E43*F43,0) | I43: Sloper | K43: 0 | L43: 0 | M43: =K43*L43
B44: 8 | C44: Disconnecting plumbing installations for demolition work. [Describe] | D44: post | E44: =K44 | F44: =CEILING(L44*$M$7,$M$8) | G44: =ROUND(E44*F44,0) | I44: Sloper | K44: 0 | L44: 0 | M44: =K44*L44
B45: 9 | C45: Disconnecting/removing IT systems for demolition work. [Describe] | D45: post | E45: =K45 | F45: =CEILING(L45*$M$7,$M$8) | G45: =ROUND(E45*F45,0) | I45: Sloper | K45: 0 | L45: 0 | M45: =K45*L45
B46: 10 | C46: Other demolition work. [Describe] | D46: post | E46: =K46 | F46: =CEILING(L46*$M$7,$M$8) | G46: =ROUND(E46*F46,0) | I46: Sloper | K46: 0 | L46: 0 | M46: =K46*L46
B47: 11 | D47: post | E47: =K47 | F47: =CEILING(L47*$M$7,$M$8) | G47: =ROUND(E47*F47,0) | I47: Sloper | K47: 0 | L47: 0 | M47: =K47*L47
B48: 12 | D48: post | E48: =K48 | F48: =CEILING(L48*$M$7,$M$8) | G48: =ROUND(E48*F48,0) | I48: Sloper | K48: 0 | L48: 0 | M48: =K48*L48
B49: 13 | D49: post | E49: =K49 | F49: =CEILING(L49*$M$7,$M$8) | G49: =ROUND(E49*F49,0) | I49: Sloper | K49: 0 | L49: 0 | M49: =K49*L49
B50: 14 | D50: post | E50: =K50 | F50: =CEILING(L50*$M$7,$M$8) | G50: =ROUND(E50*F50,0) | I50: Sloper | K50: 0 | L50: 0 | M50: =K50*L50
...

Sheet Input Procore budget
B4: Column | C4: Type | D4: Code new | E4: Code | F4: Cost type | G4: Description | H4: Manual calculation | I4: unit qty | J4: UOM | K4: Unit cost | L4: Budget amount | M4: Note
A5: CONSTRUCTION WORKS & CONSTRUCTION SITE | B5: SITE SET-UP & SUPERVISION | C5: PRM | D5: 3,1 | E5: C-1 | F5: 1 | H5: False | I5: ='4 | Calculation'!O9 | J5: m2 | K5: =L5/I5 | L5: ='4 | Calculation'!M34
B6: SITE SET-UP & SUPERVISION | C6: RF | D6: 3,1 | E6: C-1 | F6: 1 | H6: False | I6: ='4 | Calculation'!O9 | J6: m2 | K6: =L6/I6 | L6: ='4 | Calculation'!G34-'4 | Calculation'!M34
B7: DEMOLITION WORK | C7: PRM | D7: 3,3 | E7: C-2 | F7: 1 | H7: False | I7: ='4 | Calculation'!O$9 | J7: m2 | K7: =L7/I7 | L7: ='4 | Calculation'!M55
B8: DEMOLITION WORK | C8: RF | D8: 3,3 | E8: C-2 | F8: 1 | H8: False | I8: ='4 | Calculation'!O$9 | J8: m2 | K8: =L8/I8 | L8: ='4 | Calculation'!G55-'4 | Calculation'!M55
B9: MISCELLANEOUS CONSTRUCTION WORK | C9: PRM | D9: 3,15 | E9: L-9 | F9: 1 | H9: False | I9: ='4 | Calculation'!O$9 | J9: m2 | K9: =L9/I9 | L9: ='4 | Calculation'!M64
B10: MISCELLANEOUS CONSTRUCTION WORK | C10: RF | D10: 3,15 | E10: L-9 | F10: 1 | H10: False | I10: ='4 | Calculation'!O$9 | J10: m2 | K10: =L10/I10 | L10: ='4 | Calculation'!G64-'4 | Calculation'!M64
B11: STAIRCASE | C11: PRM | D11: 3,25 | E11: D-4 | F11: 1 | H11: False | I11: ='4 | Calculation'!O$9 | J11: m2 | K11: =L11/I11 | L11: ='4 | Calculation'!M79
B12: STAIRCASE | C12: RF | D12: 3,25 | E12: D-4 | F12: 1 | H12: False | I12: ='4 | Calculation'!O$9 | J12: m2 | K12: =L12/I12 | L12: ='4 | Calculation'!G79-'4 | Calculation'!M79
B13: ENTRANCES | C13: PRM | D13: 3,47 | E13: I-5 | F13: 1 | H13: False | I13: ='4 | Calculation'!O$9 | J13: m2 | K13: =L13/I13 | L13: ='4 | Calculation'!M91
B14: ENTRANCES | C14: RF | D14: 3,47 | E14: I-5 | F14: 1 | H14: False | I14: ='4 | Calculation'!O$9 | J14: m2 | K14: =L14/I14 | L14: ='4 | Calculation'!G91-'4 | Calculation'!M91
B15: KITCHEN | C15: PRM | D15: 3,48 | E15: K-4 | F15: 1 | H15: False | I15: ='4 | Calculation'!O$9 | J15: m2 | K15: =L15/I15 | L15: ='4 | Calculation'!M114
B16: KITCHEN | C16: RF | D16: 3,48 | E16: K-4 | F16: 1 | H16: False | I16: ='4 | Calculation'!O$9 | J16: m2 | K16: =L16/I16 | L16: ='4 | Calculation'!G114-'4 | Calculation'!M114
B17: OTHER | C17: PRM | D17: 3,46 | E17: G-2 | F17: 1 | H17: False | I17: ='4 | Calculation'!O$9 | J17: m2 | K17: =L17/I17 | L17: ='4 | Calculation'!M123
B18: OTHER | C18: RF | D18: 3,46 | E18: G-2 | F18: 1 | H18: False | I18: ='4 | Calculation'!O$9 | J18: m2 | K18: =L18/I18 | L18: ='4 | Calculation'!G123-'4 | Calculation'!M123
B19: TOILET AREA | C19: PRM | D19: 3,49 | E19: M-3 | F19: 1 | H19: False | I19: ='4 | Calculation'!O$9 | J19: m2 | K19: =L19/I19 | L19: ='4 | Calculation'!M145
B20: TOILET AREA | C20: RF | D20: 3,49 | E20: M-3 | F20: 1 | H20: False | I20: ='4 | Calculation'!O$9 | J20: m2 | K20: =L20/I20 | L20: ='4 | Calculation'!G145-'4 | Calculation'!M145
B21: SHOWER | C21: PRM | D21: 3,50 | E21: M-3 | F21: 1 | H21: False | I21: ='4 | Calculation'!O$9 | J21: m2 | K21: =L21/I21 | L21: ='4 | Calculation'!M165
B22: SHOWER | C22: RF | D22: 3,50 | E22: M-3 | F22: 1 | H22: False | I22: ='4 | Calculation'!O$9 | J22: m2 | K22: =L22/I22 | L22: ='4 | Calculation'!G165-'4 | Calculation'!M165
B23: STORAGE/FIRST AID/BREASTFEEDING ROOM | C23: PRM | D23: 3,51 | E23: L-6 | F23: 1 | H23: False | I23: ='4 | Calculation'!O$9 | J23: m2 | K23: =L23/I23 | L23: ='4 | Calculation'!M185
B24: STORAGE/FIRST AID/BREASTFEEDING ROOM | C24: RF | D24: 3,51 | E24: L-6 | F24: 1 | H24: False | I24: ='4 | Calculation'!O$9 | J24: m2 | K24: =L24/I24 | L24: ='4 | Calculation'!G185-'4 | Calculation'!M185
A25: INSTALLATION WORK | B25: HVAC SYSTEM | C25: PRM | D25: 3,38 | E25: M-6 | F25: 1 | H25: False | I25: ='4 | Calculation'!O$9 | J25: m2 | K25: =L25/I25 | L25: ='4 | Calculation'!M205
B26: HVAC SYSTEM | C26: RF | D26: 3,38 | E26: M-6 | F26: 1 | H26: False | I26: ='4 | Calculation'!O$9 | J26: m2 | K26: =L26/I26 | L26: ='4 | Calculation'!G205-'4 | Calculation'!M205
B27: PLUMBING WORKS | C27: PRM | D27: 3,38a | E27: M-3 | F27: 1 | H27: False | I27: ='4 | Calculation'!O$9 | J27: m2 | K27: =L27/I27 | L27: ='4 | Calculation'!M213
B28: PLUMBING WORKS | C28: RF | D28: 3,38a | E28: M-3 | F28: 1 | H28: False | I28: ='4 | Calculation'!O$9 | J28: m2 | K28: =L28/I28 | L28: ='4 | Calculation'!G213-'4 | Calculation'!M213
B29: ELECTRICAL INSTALLATION | C29: PRM | D29: 3,39 | E29: N-1 | F29: 1 | H29: False | I29: ='4 | Calculation'!O$9 | J29: m2 | K29: =L29/I29 | L29: ='4 | Calculation'!M237
B30: ELECTRICAL INSTALLATION | C30: RF | D30: 3,39 | E30: N-1 | F30: 1 | H30: False | I30: ='4 | Calculation'!O$9 | J30: m2 | K30: =L30/I30 | L30: ='4 | Calculation'!G237-'4 | Calculation'!M237
B31: ACCESS CONTROL & SECURITY | C31: PRM | D31: 3,39a | E31: K-2 | F31: 1 | H31: False | I31: ='4 | Calculation'!O$9 | J31: m2 | K31: =L31/I31 | L31: ='4 | Calculation'!M257
B32: ACCESS CONTROL & SECURITY | C32: RF | D32: 3,39a | E32: K-2 | F32: 1 | H32: False | I32: ='4 | Calculation'!O$9 | J32: m2 | K32: =L32/I32 | L32: ='4 | Calculation'!G257-'4 | Calculation'!M257
B33: IT INSTALLATION | C33: PRM | D33: 3,39c | E33: K-7 | F33: 1 | H33: False | I33: ='4 | Calculation'!O$9 | J33: m2 | K33: =L33/I33 | L33: ='4 | Calculation'!M280
B34: IT INSTALLATION | C34: RF | D34: 3,39c | E34: K-7 | F34: 1 | H34: False | I34: ='4 | Calculation'!O$9 | J34: m2 | K34: =L34/I34 | L34: ='4 | Calculation'!G280-'4 | Calculation'!M280
B35: FIRE SAFETY | C35: PRM | D35: 3,39d | E35: M-2 | F35: 1 | H35: False | I35: ='4 | Calculation'!O$9 | J35: m2 | K35: =L35/I35 | L35: ='4 | Calculation'!M304
B36: FIRE SAFETY | C36: RF | D36: 3,39d | E36: M-2 | F36: 1 | H36: False | I36: ='4 | Calculation'!O$9 | J36: m2 | K36: =L36/I36 | L36: ='4 | Calculation'!G304-'4 | Calculation'!M304
A37: FITTINGS & FIXED FITTINGS | B37: CARPETED FLOORING | C37: PRM | D37: 3,28b | E37: J-10 | F37: 1 | H37: False | I37: ='4 | Calculation'!E312 | J37: m2 | K37: =L37/I37 | L37: =SUM('4 | Calculation'!M310:M313)
B38: CARPETED FLOORING | C38: RF | D38: 3,28b | E38: J-10 | F38: 1 | H38: False | I38: ='4 | Calculation'!E312 | J38: m2 | K38: =L38/I38 | L38: =SUM('4 | Calculation'!G310:G313)-SUM('4 | Calculation'!M310:M313)
B39: PVC FLOORING | C39: PRM | D39: 3,28b | E39: J-11 | F39: 1 | H39: False | I39: ='4 | Calculation'!E318 | J39: m2 | K39: =L39/I39 | L39: =SUM('4 | Calculation'!M316:M319)
B40: PVC FLOORING | C40: RF | D40: 3,28b | E40: J-11 | F40: 1 | H40: False | I40: ='4 | Calculation'!E318 | J40: m2 | K40: =L40/I40 | L40: =SUM('4 | Calculation'!G316:G319)-SUM('4 | Calculation'!M316:M319)
B41: WOODEN FLOORING | C41: PRM | D41: 3,28b | E41: J-12 | F41: 1 | H41: False | I41: ='4 | Calculation'!E325 | J41: m2 | K41: =L41/I41 | L41: =SUM('4 | Calculation'!M322:M326)
B42: WOODEN FLOORING | C42: RF | D42: 3,28b | E42: J-12 | F42: 1 | H42: False | I42: ='4 | Calculation'!E325 | J42: m2 | K42: =L42/I42 | L42: =SUM('4 | Calculation'!G322:G326)-SUM('4 | Calculation'!M322:M326)
B43: OTHER FLOOR FINISHES | C43: PRM | D43: 3,28b | E43: J-13 | F43: 1 | H43: False | I43: ='4 | Calculation'!E331 | J43: m2 | K43: =L43/I43 | L43: =SUM('4 | Calculation'!M322:M326)
...

Sheet Measurement sheet
E6: quantity | F6: length | G6: width | H6: height | I6: circumference | J6: surface area
F7: l | G7: b | H7: h | I7: m¹ | J7: m²
B9: FLOORS
B11: 1 | C11: Space XX… | E11: 0 | I11: =E11*((2*F11)+(2*G11)) | J11: =E11*F11*G11
B12: 2 | C12: Space XX… | I12: =E12*((2*F12)+(2*G12)) | J12: =E12*F12*G12
B13: 3 | C13: Space XX… | I13: =E13*((2*F13)+(2*G13)) | J13: =E13*F13*G13
B14: 4 | C14: Space XX… | I14: =E14*((2*F14)+(2*G14)) | J14: =E14*F14*G14
B15: 5 | C15: Space XX… | I15: =E15*((2*F15)+(2*G15)) | J15: =E15*F15*G15
B16: 6 | C16: Space XX… | I16: =E16*((2*F16)+(2*G16)) | J16: =E16*F16*G16
B17: 7 | C17: Space XX… | I17: =E17*((2*F17)+(2*G17)) | J17: =E17*F17*G17
B18: 8 | C18: Space XX… | I18: =E18*((2*F18)+(2*G18)) | J18: =E18*F18*G18
B19: 9 | C19: Space XX… | I19: =E19*((2*F19)+(2*G19)) | J19: =E19*F19*G19
B20: 10 | C20: Space XX… | I20: =E20*((2*F20)+(2*G20)) | J20: =E20*F20*G20
H21: TOTAL | I21: =SUM(I11:I20) | J21: =SUM(J11:J20)
B23: WALLS 1
B25: 1 | C25: Wall XX… | I25: =E25*F25 | J25: =E25*F25*H25
B26: 2 | C26: Wall XX… | I26: =E26*F26 | J26: =E26*F26*H26
B27: 3 | C27: Wall XX… | I27: =E27*F27 | J27: =E27*F27*H27
B28: 4 | C28: Wall XX… | I28: =E28*F28 | J28: =E28*F28*H28
B29: 5 | C29: Wall XX… | I29: =E29*F29 | J29: =E29*F29*H29
B30: 6 | C30: Wall XX… | I30: =E30*F30 | J30: =E30*F30*H30
B31: 7 | C31: Wall XX… | I31: =E31*F31 | J31: =E31*F31*H31
B32: 8 | C32: Wall XX… | I32: =E32*F32 | J32: =E32*F32*H32
B33: 9 | C33: Wall XX… | I33: =E33*F33 | J33: =E33*F33*H33
B34: 10 | C34: Wall XX… | I34: =E34*F34 | J34: =E34*F34*H34
H35: TOTAL | I35: =SUM(I25:I34) | J35: =SUM(J25:J34)
H36: Glass | I36: 0 | J36: =J35*I36
H37: Close | I37: 0 | J37: =J35*I37
B39: WALLS 2
B41: 1 | C41: Wall XX… | I41: =E41*F41 | J41: =E41*F41*H41
B42: 2 | C42: Wall XX… | I42: =E42*F42 | J42: =E42*F42*H42
B43: 3 | C43: Wall XX… | I43: =E43*F43 | J43: =E43*F43*H43
B44: 4 | C44: Wall XX… | I44: =E44*F44 | J44: =E44*F44*H44
B45: 5 | C45: Wall XX… | I45: =E45*F45 | J45: =E45*F45*H45
B46: 6 | C46: Wall XX… | I46: =E46*F46 | J46: =E46*F46*H46
B47: 7 | C47: Wall XX… | I47: =E47*F47 | J47: =E47*F47*H47
B48: 8 | C48: Wall XX… | I48: =E48*F48 | J48: =E48*F48*H48
B49: 9 | C49: Wall XX… | I49: =E49*F49 | J49: =E49*F49*H49
B50: 10 | C50: Wall XX… | I50: =E50*F50 | J50: =E50*F50*H50
H51: TOTAL | I51: =SUM(I41:I50) | J51: =SUM(J41:J50)

Sheet Check quote amounts
B9: Input a la 'uitputting'
B10: In the pink colomn of the budget, we enter the supplier's name after the budget amount.
B11: If several items in the budget are allocated to the same supplier we can check the total
B12: here to see if it matches the quote received.
B14: Name | C14: Total amount
B15: - | C15: =SUMIF('4 | Calculation'!$I$18:$I$617,'Check quote amounts'!B15,'4 | Calculation'!$M$18:$M$617)
B16: - | C16: =SUMIF('4 | Calculation'!$I$18:$I$617,'Check quote amounts'!B16,'4 | Calculation'!$M$18:$M$617)
B17: - | C17: =SUMIF('4 | Calculation'!$I$18:$I$617,'Check quote amounts'!B17,'4 | Calculation'!$M$18:$M$617)
B18: - | C18: =SUMIF('4 | Calculation'!$I$18:$I$617,'Check quote amounts'!B18,'4 | Calculation'!$M$18:$M$617)
B19: - | C19: =SUMIF('4 | Calculation'!$I$18:$I$617,'Check quote amounts'!B19,'4 | Calculation'!$M$18:$M$617)
B20: - | C20: =SUMIF('4 | Calculation'!$I$18:$I$617,'Check quote amounts'!B20,'4 | Calculation'!$M$18:$M$617)
B21: - | C21: =SUMIF('4 | Calculation'!$I$18:$I$617,'Check quote amounts'!B21,'4 | Calculation'!$M$18:$M$617)
B22: - | C22: =SUMIF('4 | Calculation'!$I$18:$I$617,'Check quote amounts'!B22,'4 | Calculation'!$M$18:$M$617)
B23: - | C23: =SUMIF('4 | Calculation'!$I$18:$I$617,'Check quote amounts'!B23,'4 | Calculation'!$M$18:$M$617)
B24: - | C24: =SUMIF('4 | Calculation'!$I$18:$I$617,'Check quote amounts'!B24,'4 | Calculation'!$M$18:$M$617)
B25: - | C25: =SUMIF('4 | Calculation'!$I$18:$I$617,'Check quote amounts'!B25,'4 | Calculation'!$M$18:$M$617)
B26: - | C26: =SUMIF('4 | Calculation'!$I$18:$I$617,'Check quote amounts'!B26,'4 | Calculation'!$M$18:$M$617)
... B38: - | C38: =SUMIF('4 | Calculation'!$I$18:$I$617,'Check quote amounts'!B38,'4 | Calculation'!$M$18:$M$617)
B39: - | C39: =SUMIF('4 | Calculation'!$I$18:$I$618,'Check quote amounts'!B39,'4 | Calculation'!$M$18:$M$618)
C41: =SUM(C15:C39)

Sheet Data
A1: Categorie
A2: post
A3: stelpost
A4: p.m.
A5: m1
A6: m2
A7: stuks
